2025-09-02 22:49:00,381 - root - INFO - Starting Database Loader
2025-09-02 22:49:00,383 - root - ERROR - ‚ùå Error during database loading: 
Traceback (most recent call last):
  File "/opt/homebrew/Cellar/python@3.13/3.13.3/Frameworks/Python.framework/Versions/3.13/lib/python3.13/getpass.py", line 68, in unix_getpass
    old = termios.tcgetattr(fd)     # a copy to save
termios.error: (19, 'Operation not supported by device')

During handling of the above exception, another exception occurred:

Traceback (most recent call last):
  File "/Users/jaristizabal/Documents/Proyecto ETL/src/database_loader.py", line 493, in main
    db_config = get_db_config()
  File "/Users/jaristizabal/Documents/Proyecto ETL/src/database_loader.py", line 411, in get_db_config
    password = getpass.getpass("Enter MySQL password: ")
  File "/opt/homebrew/Cellar/python@3.13/3.13.3/Frameworks/Python.framework/Versions/3.13/lib/python3.13/getpass.py", line 90, in unix_getpass
    passwd = fallback_getpass(prompt, stream)
  File "/opt/homebrew/Cellar/python@3.13/3.13.3/Frameworks/Python.framework/Versions/3.13/lib/python3.13/getpass.py", line 126, in fallback_getpass
    return _raw_input(prompt, stream)
  File "/opt/homebrew/Cellar/python@3.13/3.13.3/Frameworks/Python.framework/Versions/3.13/lib/python3.13/getpass.py", line 148, in _raw_input
    raise EOFError
EOFError
